<?xml version="1.0" ?>

<sdf version='1.9'>
  <model name='URDF'>
    <link name='base_link'>
      <inertial>
        <pose>0.04438135250210484 -0.1061778793367964 0.04733381165238545 0 0 0</pose>
        <mass>25.1623688204694</mass>
        <inertia>
          <ixx>0.1098716038830415</ixx>
          <ixy>0.00025559737379302061</ixy>
          <ixz>0.00092271634194572572</ixz>
          <iyy>0.072372669004639165</iyy>
          <iyz>-0.0029964494892606862</iyz>
          <izz>0.132267591521045</izz>
        </inertia>
      </inertial>
      <collision name='base_link_fixed_joint_lump__caster_link_collision'>
        <pose>0 0 0 0 0 0</pose>
        <geometry>
          <mesh>
            <scale>0.001 0.001 0.001</scale>
            <uri>file:/home/fionn/sec_bot_ws/src/sec_bot_ros2/meshes/caster_link_1.stl</uri>
          </mesh>
        </geometry>
      </collision>
      <collision name='base_link_fixed_joint_lump__chassis_link_collision_1'>
        <pose>0 0 0 0 0 0</pose>
        <geometry>
          <mesh>
            <scale>0.001 0.001 0.001</scale>
            <uri>file:/home/fionn/sec_bot_ws/src/sec_bot_ros2/meshes/base_link.stl</uri>
          </mesh>
        </geometry>
      </collision>
      <collision name='base_link_fixed_joint_lump__lidar_link_collision_2'>
        <pose>0 0 0 0 0 0</pose>
        <geometry>
          <mesh>
            <scale>0.001 0.001 0.001</scale>
            <uri>file:/home/fionn/sec_bot_ws/src/sec_bot_ros2/meshes/lidar_link_1.stl</uri>
          </mesh>
        </geometry>
      </collision>
      <visual name='base_link_fixed_joint_lump__caster_link_visual'>
        <pose>0 0 0 0 0 0</pose>
        <geometry>
          <mesh>
            <scale>0.001 0.001 0.001</scale>
            <uri>file:/home/fionn/sec_bot_ws/src/sec_bot_ros2/meshes/caster_link_1.stl</uri>
          </mesh>
        </geometry>
        <material>
          <diffuse>0 0 0 1</diffuse>
          <ambient>0 0 0 1</ambient>
        </material>
      </visual>
      <visual name='base_link_fixed_joint_lump__chassis_link_visual_1'>
        <pose>0 0 0 0 0 0</pose>
        <geometry>
          <mesh>
            <scale>0.001 0.001 0.001</scale>
            <uri>file:/home/fionn/sec_bot_ws/src/sec_bot_ros2/meshes/base_link.stl</uri>
          </mesh>
        </geometry>
        <material>
          <diffuse>0 0 0 1</diffuse>
          <ambient>0 0 0 1</ambient>
        </material>
      </visual>
      <visual name='base_link_fixed_joint_lump__lidar_link_visual_2'>
        <pose>0 0 0 0 0 0</pose>
        <geometry>
          <mesh>
            <scale>0.001 0.001 0.001</scale>
            <uri>file:/home/fionn/sec_bot_ws/src/sec_bot_ros2/meshes/lidar_link_1.stl</uri>
          </mesh>
        </geometry>
        <material>
          <diffuse>0 0 0 1</diffuse>
          <ambient>0 0 0 1</ambient>
        </material>
      </visual>
    </link>
    <joint name='left_wheel_joint' type='revolute'>
      <pose relative_to='base_link'>-0.075 -0.065937 0.03563 0 0 0</pose>
      <parent>base_link</parent>
      <child>left_wheel_link</child>
      <axis>
        <xyz>-1 0 0</xyz>
        <limit>
          <lower>-10000000000000000</lower>
          <upper>10000000000000000</upper>
        </limit>
        <dynamics>
          <spring_reference>0</spring_reference>
          <spring_stiffness>0</spring_stiffness>
        </dynamics>
      </axis>
    </joint>
    <link name='left_wheel_link'>
      <pose relative_to='left_wheel_joint'>0 0 0 0 0 0</pose>
      <inertial>
        <pose>0 0 0 0 0 0</pose>
        <mass>2.6048711836780609</mass>
        <inertia>
          <ixx>0.0055030000000000001</ixx>
          <ixy>0</ixy>
          <ixz>0</ixz>
          <iyy>0.0028869999999999998</iyy>
          <iyz>0</iyz>
          <izz>0.0028869999999999998</izz>
        </inertia>
      </inertial>
      <collision name='left_wheel_link_collision'>
        <pose>0.075 0.065937 -0.03563 0 0 0</pose>
        <geometry>
          <mesh>
            <scale>0.001 0.001 0.001</scale>
            <uri>file:/home/fionn/sec_bot_ws/src/sec_bot_ros2/meshes/left_wheel_link_1.stl</uri>
          </mesh>
        </geometry>
      </collision>
      <visual name='left_wheel_link_visual'>
        <pose>0.075 0.065937 -0.03563 0 0 0</pose>
        <geometry>
          <mesh>
            <scale>0.001 0.001 0.001</scale>
            <uri>file:/home/fionn/sec_bot_ws/src/sec_bot_ros2/meshes/left_wheel_link_1.stl</uri>
          </mesh>
        </geometry>
        <material>
          <diffuse>0 0 0 1</diffuse>
          <ambient>0 0 0 1</ambient>
        </material>
      </visual>
    </link>
    <joint name='right_wheel_joint' type='revolute'>
      <pose relative_to='base_link'>0.075 -0.065937 0.03563 0 0 0</pose>
      <parent>base_link</parent>
      <child>right_wheel_link</child>
      <axis>
        <xyz>-1 0 0</xyz>
        <limit>
          <lower>-10000000000000000</lower>
          <upper>10000000000000000</upper>
        </limit>
        <dynamics>
          <spring_reference>0</spring_reference>
          <spring_stiffness>0</spring_stiffness>
        </dynamics>
      </axis>
    </joint>
    <link name='right_wheel_link'>
      <pose relative_to='right_wheel_joint'>0 0 0 0 0 0</pose>
      <inertial>
        <pose>-0.03054194831388796 -0.001957133202892432 -0.007340509604943389 0 0 0</pose>
        <mass>2.6048711836780609</mass>
        <inertia>
          <ixx>0.0055030000000000001</ixx>
          <ixy>0</ixy>
          <ixz>0</ixz>
          <iyy>0.0028869999999999998</iyy>
          <iyz>0</iyz>
          <izz>0.0028869999999999998</izz>
        </inertia>
      </inertial>
      <collision name='right_wheel_link_collision'>
        <pose>-0.075 0.065937 -0.03563 0 0 0</pose>
        <geometry>
          <mesh>
            <scale>0.001 0.001 0.001</scale>
            <uri>file:/home/fionn/sec_bot_ws/src/sec_bot_ros2/meshes/right_wheel_link_1.stl</uri>
          </mesh>
        </geometry>
      </collision>
      <visual name='right_wheel_link_visual'>
        <pose>-0.075 0.065937 -0.03563 0 0 0</pose>
        <geometry>
          <mesh>
            <scale>0.001 0.001 0.001</scale>
            <uri>file:/home/fionn/sec_bot_ws/src/sec_bot_ros2/meshes/right_wheel_link_1.stl</uri>
          </mesh>
        </geometry>
        <material>
          <diffuse>0 0 0 1</diffuse>
          <ambient>0 0 0 1</ambient>
        </material>
      </visual>
    </link>
    <frame name='caster_joint' attached_to='base_link'>
      <pose>0 -0.196024 -0.01 0 -0 0</pose>
    </frame>
    <frame name='caster_link' attached_to='caster_joint'/>
    <frame name='chassis_joint' attached_to='base_link'>
      <pose>0 0 0 0 -0 0</pose>
    </frame>
    <frame name='chassis_link' attached_to='chassis_joint'/>
    <frame name='lidar_joint' attached_to='base_link'>
      <pose>0 -0.079076 0.100631 0 -0 0</pose>
    </frame>
    <frame name='lidar_link' attached_to='lidar_joint'/>
  </model>
</sdf>
