<?xml version="1.0" ?>

<sdf version='1.9'>
  <model name='sec_bot'>
    <link name='base_link'>
      <inertial>
        <pose>0 0.0 0 0 0 0</pose>
        <mass>20</mass>
        <inertia>
          <ixx>2.311013729268808</ixx>
          <ixy>-6.5602677068582406e-19</ixy>
          <ixz>-5.43315392675936e-18</ixz>
          <iyy>2.3065445000000002</iyy>
          <iyz>-0.037013749493832002</iyz>
          <izz>2.0044692292688082</izz>
        </inertia>
      </inertial>
      <visual name='base_link_fixed_joint_lump__chassis_visual'>
        <pose>0 -0.3204565785598161 -0.005000000000000004 -6.123233995736767e-17 0 0</pose>
        <geometry>
          <mesh>
            <scale>1 1 1</scale>
            <uri>file:/carProject_ws/src/ros2_car_project/description/onshapeTest/chassis.stl</uri>
          </mesh>
        </geometry>
        <material>
          <diffuse>0.769608 1 1 1</diffuse>
          <ambient>0.769608 1 1 1</ambient>
        </material>
      </visual>
      <visual name='base_link_fixed_joint_lump__lidar_visual_1'>
        <pose>-1.489764093506481e-09 -0.320456578559816 1.571 3.141592653589793 3.442867999292233e-42 3.14159265</pose>
        <geometry>
          <mesh>
            <scale>1 1 1</scale>
            <uri>file:/carProject_ws/src/ros2_car_project/description/onshapeTest/lidar.stl</uri>
          </mesh>
        </geometry>
        <material>
          <diffuse>0.960784 1 1 1</diffuse>
          <ambient>0.960784 1 1 1</ambient>
        </material>
      </visual>

      <sensor name='gpu_lidar' type='gpu_lidar'>"
        <pose relative_to='lidar'>0 0 0 0 0 0</pose>
        <topic>lidar</topic>
        <update_rate>10</update_rate>
        <ray>
          <scan>
            <horizontal>
              <samples>200</samples>
              <resolution>1</resolution>
              <min_angle>-3.141592653</min_angle>
              <max_angle>3.141592653</max_angle>
            </horizontal>
            <vertical>
              <samples>1</samples>
              <resolution>0.01</resolution>
              <min_angle>0</min_angle>
              <max_angle>0</max_angle>
            </vertical>
          </scan>
          <range>
            <min>0.08</min>
            <max>10.0</max>
            <resolution>0.01</resolution>
          </range>
        </ray>
        <always_on>1</always_on>
        <visualize>true</visualize>
        <gz_frame_id>lidar</gz_frame_id>
      </sensor>  

    </link>
    <joint name='back_left_wheel_joint' type='revolute'>
      <pose relative_to='base_link'>0.28 0.0245434214401839 0.00475609756097601 -1.570796326794897 0 1.570796326794897</pose>
      <parent>base_link</parent>
      <child>back_left_wheel_link</child>
      <axis>
        <xyz>0 0 -1</xyz>
        <limit>
          <lower>-10000000000000000</lower>
          <upper>10000000000000000</upper>
        </limit>
        <dynamics>
          <spring_reference>0</spring_reference>
          <spring_stiffness>0</spring_stiffness>
        </dynamics>
      </axis>
    </joint>
    <link name='back_left_wheel_link'>
      <pose relative_to='back_left_wheel_joint'>0 0 0 0 0 0</pose>
      <inertial>
        <pose>0 0 0 0 0 0</pose>
        <mass>1</mass>
        <inertia>
          <ixx>1</ixx>
          <ixy>0</ixy>
          <ixz>0</ixz>
          <iyy>1</iyy>
          <iyz>0</iyz>
          <izz>1</izz>
        </inertia>
      </inertial>
      <collision name='back_left_wheel_link_collision'>
        <pose>0 0 0 0 1.570796326794897 -1.570796326794897</pose>
        <geometry>
          <sphere>
            <radius>0.1525</radius>
          </sphere>
        </geometry>
        <surface>
          <friction>
            <ode>
              <mu>10000</mu>
              <mu2>10000</mu2>
            </ode>
          </friction>
        </surface>
      </collision>
      <visual name='back_left_wheel_link_visual'>
        <pose>0.4049999999999999 -1.734723475976807e-17 0.283 0 1.570796326794897 -1.570796326794897</pose>
        <geometry>
          <mesh>
            <scale>1 1 1</scale>
            <uri>file:/carProject_ws/src/ros2_car_project/description/onshapeTest/wheel.stl</uri>
          </mesh>
        </geometry>
        <material>
          <diffuse>0.808824 0.808824 0.808824 1</diffuse>
          <ambient>0.808824 0.808824 0.808824 1</ambient>
        </material>
      </visual>
    </link>
    <joint name='back_right_wheel_joint' type='revolute'>
      <pose relative_to='base_link'>-0.28 0.0245434214401839 0.00475609756097601 1.570796326794896 0 1.570796326794896</pose>
      <parent>base_link</parent>
      <child>back_right_wheel_link</child>
      <axis>
        <xyz>0 0 1</xyz>
        <limit>
          <lower>-10000000000000000</lower>
          <upper>10000000000000000</upper>
        </limit>
        <dynamics>
          <spring_reference>0</spring_reference>
          <spring_stiffness>0</spring_stiffness>
        </dynamics>
      </axis>
    </joint>
    <link name='back_right_wheel_link'>
      <pose relative_to='back_right_wheel_joint'>0 0 0 0 0 0</pose>
      <inertial>
        <pose>0 0 0 0 0 0</pose>
        <mass>1</mass>
        <inertia>
          <ixx>1</ixx>
          <ixy>0</ixy>
          <ixz>0</ixz>
          <iyy>1</iyy>
          <iyz>0</iyz>
          <izz>1</izz>
        </inertia>
      </inertial>
      <collision name='back_right_wheel_link_collision'>
        <pose>0 0 0 0 -1.570796326794897 -1.570796326794897</pose>
        <geometry>
          <sphere>
            <radius>0.1525</radius>
          </sphere>
        </geometry>
        <surface>
          <friction>
            <ode>
              <mu>10000</mu>
              <mu2>10000</mu2>
            </ode>
          </friction>
        </surface>
      </collision>
      <visual name='back_right_wheel_link_visual'>
        <pose>0.4049999999999999 1.734723475976807e-17 -0.393 0 -1.570796326794897 -1.570796326794897</pose>
        <geometry>
          <mesh>
            <scale>1 1 1</scale>
            <uri>file:/carProject_ws/src/ros2_car_project/description/onshapeTest/wheel.stl</uri>
          </mesh>
        </geometry>
        <material>
          <diffuse>0.808824 0.808824 0.808824 1</diffuse>
          <ambient>0.808824 0.808824 0.808824 1</ambient>
        </material>
      </visual>
    </link>
    <joint name='left_steering_joint' type='revolute'>
      <pose relative_to='base_link'>0.2125 -0.7254565785598159 0.0575 -6.123233995736764e-17 6.162975822039171e-32 -1.387778780781449e-17</pose>
      <parent>base_link</parent>
      <child>left_steering_link</child>
      <axis>
        <xyz>0 0 1</xyz>
        <limit>
          <lower>-0.25</lower>
          <upper>0.25</upper>
          <effort>10</effort>
          <velocity>3</velocity>
        </limit>
        <dynamics>
          <damping>0</damping>
          <friction>0</friction>
          <spring_reference>0</spring_reference>
          <spring_stiffness>0</spring_stiffness>
        </dynamics>
      </axis>
    </joint>
    <link name='left_steering_link'>
      <pose relative_to='left_steering_joint'>0 0 0 0 0 0</pose>
      <inertial>
        <pose>0 0 0 0 0 0</pose>
        <mass>1</mass>
        <inertia>
          <ixx>1</ixx>
          <ixy>0</ixy>
          <ixz>0</ixz>
          <iyy>1</iyy>
          <iyz>0</iyz>
          <izz>1</izz>
        </inertia>
      </inertial>
      <visual name='left_steering_link_visual'>
        <pose>-0.2125 0.4049999999999999 -0.06949999999999998 0 0 3.773734306841385e-48</pose>
        <geometry>
          <mesh>
            <scale>1 1 1</scale>
            <uri>file:/carProject_ws/src/ros2_car_project/description/onshapeTest/steering_link.stl</uri>
          </mesh>
        </geometry>
        <material>
          <diffuse>1 1 1 1</diffuse>
          <ambient>1 1 1 1</ambient>
        </material>
      </visual>
    </link>
    <joint name='front_left_wheel_joint' type='revolute'>
      <pose relative_to='left_steering_link'>0.07050000000000003 0 -0.06950000000000001 -1.570796326794897 -3.663735981263015e-15 1.570796326794898</pose>
      <parent>left_steering_link</parent>
      <child>front_left_wheel_link</child>
      <axis>
        <xyz>0 0 1</xyz>
        <limit>
          <lower>-10000000000000000</lower>
          <upper>10000000000000000</upper>
        </limit>
        <dynamics>
          <spring_reference>0</spring_reference>
          <spring_stiffness>0</spring_stiffness>
        </dynamics>
      </axis>
    </joint>
    <link name='front_left_wheel_link'>
      <pose relative_to='front_left_wheel_joint'>0 0 0 0 0 0</pose>
      <inertial>
        <pose>0 0 0 0 0 0</pose>
        <mass>1</mass>
        <inertia>
          <ixx>1</ixx>
          <ixy>0</ixy>
          <ixz>0</ixz>
          <iyy>1</iyy>
          <iyz>0</iyz>
          <izz>1</izz>
        </inertia>
      </inertial>
      <collision name='front_left_wheel_link_collision'>
        <pose>0 0 0 0 1.570796326794897 -1.570796326794897</pose>
        <geometry>
          <sphere>
            <radius>0.1525</radius>
          </sphere>
        </geometry>
        <surface>
          <friction>
            <ode>
              <mu>10000</mu>
              <mu2>10000</mu2>
            </ode>
          </friction>
        </surface>
      </collision>
      <visual name='front_left_wheel_link_visual'>
        <pose>0.4049999999999999 -1.734723475976807e-17 0.283 0 1.570796326794897 -1.570796326794897</pose>
        <geometry>
          <mesh>
            <scale>1 1 1</scale>
            <uri>file:/carProject_ws/src/ros2_car_project/description/onshapeTest/wheel.stl</uri>
          </mesh>
        </geometry>
        <material>
          <diffuse>0.808824 0.808824 0.808824 1</diffuse>
          <ambient>0.808824 0.808824 0.808824 1</ambient>
        </material>
      </visual>
    </link>
    <joint name='right_steering_joint' type='revolute'>
      <pose relative_to='base_link'>-0.2125 -0.725456578559816 0.0575 6.123233995737089e-17 -2.02047753006521e-31 3.141592653589793</pose>
      <parent>base_link</parent>
      <child>right_steering_link</child>
      <axis>
        <xyz>0 0 1</xyz>
        <limit>
          <lower>-0.25</lower>
          <upper>0.25</upper>
          <effort>10</effort>
          <velocity>3</velocity>
        </limit>
        <dynamics>
          <damping>0</damping>
          <friction>0</friction>
          <spring_reference>0</spring_reference>
          <spring_stiffness>0</spring_stiffness>
        </dynamics>
      </axis>
    </joint>
    <link name='right_steering_link'>
      <pose relative_to='right_steering_joint'>0 0 0 0 0 0</pose>
      <inertial>
        <pose>0 0 0 0 0 0</pose>
        <mass>1</mass>
        <inertia>
          <ixx>1</ixx>
          <ixy>0</ixy>
          <ixz>0</ixz>
          <iyy>1</iyy>
          <iyz>0</iyz>
          <izz>1</izz>
        </inertia>
      </inertial>
      <visual name='right_steering_link_visual'>
        <pose>-0.2125 0.4049999999999999 -0.06949999999999998 0 0 5.57569156163461e-50</pose>
        <geometry>
          <mesh>
            <scale>1 1 1</scale>
            <uri>file:/carProject_ws/src/ros2_car_project/description/onshapeTest/steering_link.stl</uri>
          </mesh>
        </geometry>
        <material>
          <diffuse>1 1 1 1</diffuse>
          <ambient>1 1 1 1</ambient>
        </material>
      </visual>
    </link>
    <joint name='front_right_wheel_joint' type='revolute'>
      <pose relative_to='right_steering_link'>0.07049999999999995 -5.551115123125783e-17 -0.06949999999999999 -1.570796326794896 -1.178999914605355 1.570796326794896</pose>
      <parent>right_steering_link</parent>
      <child>front_right_wheel_link</child>
      <axis>
        <xyz>0 0 1</xyz>
        <limit>
          <lower>-10000000000000000</lower>
          <upper>10000000000000000</upper>
        </limit>
        <dynamics>
          <spring_reference>0</spring_reference>
          <spring_stiffness>0</spring_stiffness>
        </dynamics>
      </axis>
    </joint>
    <link name='front_right_wheel_link'>
      <pose relative_to='front_right_wheel_joint'>0 0 0 0 0 0</pose>
      <inertial>
        <pose>0 0 0 0 0 0</pose>
        <mass>1</mass>
        <inertia>
          <ixx>1</ixx>
          <ixy>0</ixy>
          <ixz>0</ixz>
          <iyy>1</iyy>
          <iyz>0</iyz>
          <izz>1</izz>
        </inertia>
      </inertial>
      <collision name='front_right_wheel_link_collision'>
        <pose>0 0 0 0 -1.570796326794897 -1.570796326794897</pose>
        <geometry>
          <sphere>
            <radius>0.1525</radius>
          </sphere>
        </geometry>
        <surface>
          <friction>
            <ode>
              <mu>10000</mu>
              <mu2>10000</mu2>
            </ode>
          </friction>
        </surface>
      </collision>
      <visual name='front_right_wheel_link_visual'>
        <pose>0.405 2.775557561562891e-17 -0.393 0 -1.570796326794897 -1.570796326794897</pose>
        <geometry>
          <mesh>
            <scale>1 1 1</scale>
            <uri>file:/carProject_ws/src/ros2_car_project/description/onshapeTest/wheel.stl</uri>
          </mesh>
        </geometry>
        <material>
          <diffuse>0.808824 0.808824 0.808824 1</diffuse>
          <ambient>0.808824 0.808824 0.808824 1</ambient>
        </material>
      </visual>
    </link>
    <frame name='base_footprint_joint' attached_to='base_link'>
      <pose>0 0 0 0 -0 0</pose>
    </frame>
    <frame name='base_footprint' attached_to='base_footprint_joint'/>
    <frame name='chassis_joint' attached_to='base_link'>
      <pose>0 0 0 0 -0 0</pose>
    </frame>
    <frame name='chassis' attached_to='chassis_joint'/>
    <frame name='lidar_joint' attached_to='base_link'>
      <pose>0 0.094543 0.783 0 -0 3.14159</pose>
    </frame>
    <frame name='lidar' attached_to='lidar_joint'>  
      <pose>0 0 0 0 -0 3.1415926535</pose>                           
    </frame>

    <!-- <plugin
			filename="ignition-gazebo-ackermann-steering-system"
			name="ignition::gazebo::systems::AckermannSteering">
			<left_joint>back_left_wheel_joint</left_joint>
			<right_joint>back_right_wheel_joint</right_joint>
      <left_steering_joint>left_steering_joint</left_steering_joint>
			<right_steering_joint>right_steering_joint</right_steering_joint>
			<wheel_separation>0.71</wheel_separation>
      <kingpin_width>0.44</kingpin_width>
      <wheel_base>0.76</wheel_base>
      <steering_limit>0.456</steering_limit>
			<wheel_radius>0.1525</wheel_radius>
			<odom_publish_frequency>50</odom_publish_frequency>
			<max_acceleration>1.5</max_acceleration>
			<min_acceleration>-1.5</min_acceleration>
			<max_velocity>3.13</max_velocity>
			<min_velocity>-3.13</min_velocity>
    </plugin> -->

    <plugin
      filename="gz-sim-joint-controller-system"
      name="gz::sim::systems::JointController">
      <joint_name>back_right_wheel_joint</joint_name>
      <initial_velocity>0.0</initial_velocity>
      <topic>car_model/wheel_speed</topic>
      <use_force_commands>true</use_force_commands>
      <p_gain>5.0</p_gain>
      <i_gain>0.05</i_gain>
    </plugin>

    <plugin
      filename="gz-sim-joint-controller-system"
      name="gz::sim::systems::JointController">
      <joint_name>back_left_wheel_joint</joint_name>
      <initial_velocity>0.0</initial_velocity>
      <topic>car_model/wheel_speed</topic>
      <use_force_commands>true</use_force_commands>
      <p_gain>5.0</p_gain>
      <i_gain>0.05</i_gain>
    </plugin>

    <plugin
      filename="gz-sim-joint-position-controller-system"
      name="gz::sim::systems::JointPositionController">
      <joint_name>left_steering_joint</joint_name>
      <topic>car_model/steering_angle</topic>
      <p_gain>10</p_gain>
      <i_gain>0.05</i_gain>
      <d_gain>0.01</d_gain>
      <i_max>1</i_max>
      <i_min>-1</i_min>
      <cmd_max>0.456</cmd_max>
      <cmd_min>-0.456</cmd_min>
    </plugin>

    <plugin
      filename="gz-sim-joint-position-controller-system"
      name="gz::sim::systems::JointPositionController">
      <joint_name>right_steering_joint</joint_name>
      <topic>car_model/steering_angle</topic>
      <p_gain>10</p_gain>
      <i_gain>0.05</i_gain>
      <d_gain>0.01</d_gain>
      <i_max>1</i_max>
      <i_min>-1</i_min>
      <cmd_max>0.456</cmd_max>
      <cmd_min>-0.456</cmd_min>
    </plugin>

    <plugin
      filename="gz-sim-joint-state-publisher-system"
      name="gz::sim::systems::JointStatePublisher">
      <topic>car_model/joint_states</topic>
      <!-- <joint_name>back_right_wheel_joint</joint_name>
      <joint_name>back_left_wheel_joint</joint_name>
      <joint_name>left_steering_joint</joint_name> -->
    </plugin>

    <plugin
      filename="gz-sim-sensors-system"
      name="ignition::gazebo::systems::Sensors">
      <render_engine>ogre2</render_engine>
    </plugin>
  </model>
</sdf>
